<?xml version="1.0" ?>
<robot name="Robotic" xmlns:xacro="http://www.ros.org/wiki/xacro">

  <link name="world"/>

  <link name="base_link">
    <visual>
      <origin xyz="0 0 0" rpy="0 0 0"/>
      <geometry>
        <mesh filename="package://roboticarm_description/meshes/base_link.stl" scale="0.01 0.01 0.01"/>
      </geometry>
    </visual>
  </link>

  <joint name="base_joint" type="fixed">
    <parent link="world"/>
    <child link="base_link"/>
    <origin xyz="0 0 0" rpy="0 0 0"/>
  </joint>

  <link name="waist_link">
    <visual>
      <origin xyz="0 0 0" rpy="0 0 0"/>
      <geometry>
        <mesh filename="package://roboticarm_description/meshes/Waist_1.stl" scale="0.01 0.01 0.01"/>
      </geometry>
    </visual>
  </link>

  <joint name="waist_joint" type="revolute">
    <parent link="base_link"/>
    <child link="waist_link"/>
    <origin xyz="0 0 0" rpy="0 0 0"/>
    <axis xyz="0 0 1"/>
    <limit lower="-3.14" upper="3.14" effort="100" velocity="1"/>
  </joint>

  <link name="arm_1_link">
    <visual>
      <origin xyz="0 0 0" rpy="0 0 0"/>
      <geometry>
        <mesh filename="package://roboticarm_description/meshes/Arm01_1.stl" scale="0.01 0.01 0.01"/>
      </geometry>
    </visual>
  </link>

  <joint name="arm_1_joint" type="revolute">
    <parent link="waist_link"/>
    <child link="arm_1_link"/>
    <origin xyz="0 0 0" rpy="0 0 0"/>
    <axis xyz="0 1 0"/>
    <limit lower="-3.14" upper="3.14" effort="100" velocity="1"/>
  </joint>

  <link name="arm_2_link">
    <visual>
      <origin xyz="0 0 0" rpy="0 0 0"/>
      <geometry>
        <mesh filename="package://roboticarm_description/meshes/Arm02_1.stl" scale="0.01 0.01 0.01"/>
      </geometry>
    </visual>
  </link>

  <joint name="arm_2_joint" type="revolute">
    <parent link="arm_1_link"/>
    <child link="arm_2_link"/>
    <origin xyz="0 0 0" rpy="0 0 0"/>
    <axis xyz="0 1 0"/>
    <limit lower="-3.14" upper="3.14" effort="100" velocity="1"/>
  </joint> 

  <link name="arm_3_link">
    <visual>
      <origin xyz="0 0 0" rpy="0 0 0"/>
      <geometry>
        <mesh filename="package://roboticarm_description/meshes/Arm03_1.stl" scale="0.01 0.01 0.01"/>
      </geometry>
    </visual>
  </link>

  <joint name="arm_3_joint" type="revolute">
    <parent link="arm_2_link"/>
    <child link="arm_3_link"/>
    <origin xyz="0 0 0" rpy="0 0 0"/>
    <axis xyz="0 1 0"/>
    <limit lower="-3.14" upper="3.14" effort="100" velocity="1"/>
  </joint>


</robot>
